2025-10-29 22:04:00,231 - root - ERROR - Error al crear base de datos: 1045 (28000): Access denied for user 'root'@'localhost' (using password: YES)
2025-10-29 22:04:00,231 - root - ERROR - Error de BD en create_database_and_tables: Error al crear base de datos: 1045 (28000): Access denied for user 'root'@'localhost' (using password: YES)
2025-10-29 22:04:23,870 - root - ERROR - Error al conectar con la base de datos (intento 1): 1045 (28000): Access denied for user 'root'@'localhost' (using password: YES)
2025-10-29 22:04:23,872 - root - ERROR - Error inesperado en execute_query: Traceback (most recent call last):
  File "/Users/paulrichardmunozbruno/Library/Python/3.14/lib/python/site-packages/mysql/connector/connection_cext.py", line 354, in _open_connection
    self._cmysql.connect(**cnx_kwargs)
    ~~~~~~~~~~~~~~~~~~~~^^^^^^^^^^^^^^
_mysql_connector.MySQLInterfaceError: Access denied for user 'root'@'localhost' (using password: YES)

The above exception was the direct cause of the following exception:

Traceback (most recent call last):
  File "/Users/paulrichardmunozbruno/Desktop/proyecto tecnicas de programacion/Gestion_Alimentos.py", line 221, in connect
    self.conn = mysql.connector.connect(
                ~~~~~~~~~~~~~~~~~~~~~~~^
        host=config['db_host'],
        ^^^^^^^^^^^^^^^^^^^^^^^
    ...<5 lines>...
        autocommit=False  # Control manual de transacciones
        ^^^^^^^^^^^^^^^^^^^^^^^^^^^^^^^^^^^^^^^^^^^^^^^^^^^
    )
    ^
  File "/Users/paulrichardmunozbruno/Library/Python/3.14/lib/python/site-packages/mysql/connector/pooling.py", line 322, in connect
    return CMySQLConnection(*args, **kwargs)
  File "/Users/paulrichardmunozbruno/Library/Python/3.14/lib/python/site-packages/mysql/connector/connection_cext.py", line 142, in __init__
    self.connect(**kwargs)
    ~~~~~~~~~~~~^^^^^^^^^^
  File "/Users/paulrichardmunozbruno/Library/Python/3.14/lib/python/site-packages/mysql/connector/abstracts.py", line 1604, in connect
    self._open_connection()
    ~~~~~~~~~~~~~~~~~~~~~^^
  File "/Users/paulrichardmunozbruno/Library/Python/3.14/lib/python/site-packages/mysql/connector/connection_cext.py", line 360, in _open_connection
    raise get_mysql_exception(
        err.errno, msg=err.msg, sqlstate=err.sqlstate
    ) from err
mysql.connector.errors.ProgrammingError: 1045 (28000): Access denied for user 'root'@'localhost' (using password: YES)

During handling of the above exception, another exception occurred:

Traceback (most recent call last):
  File "/Users/paulrichardmunozbruno/Desktop/proyecto tecnicas de programacion/Gestion_Alimentos.py", line 257, in execute_query
    conn = self.connect()
  File "/Users/paulrichardmunozbruno/Desktop/proyecto tecnicas de programacion/Gestion_Alimentos.py", line 244, in connect
    raise DatabaseError(error_message)
DatabaseError: Error al conectar con la base de datos (intento 1): 1045 (28000): Access denied for user 'root'@'localhost' (using password: YES)

2025-10-29 22:04:23,872 - root - ERROR - Error en la BD durante la inicialización de usuarios: Error inesperado: Error al conectar con la base de datos (intento 1): 1045 (28000): Access denied for user 'root'@'localhost' (using password: YES). La tabla 'usuarios' podría no existir.
2025-10-29 22:04:25,520 - root - INFO - Aplicación cerrada por el usuario
2025-10-29 22:06:49,716 - root - ERROR - Error al conectar con la base de datos (intento 1): 1045 (28000): Access denied for user 'root'@'localhost' (using password: YES)
2025-10-29 22:06:49,719 - root - ERROR - Error inesperado en execute_query: Traceback (most recent call last):
  File "/Users/paulrichardmunozbruno/Library/Python/3.14/lib/python/site-packages/mysql/connector/connection_cext.py", line 354, in _open_connection
    self._cmysql.connect(**cnx_kwargs)
    ~~~~~~~~~~~~~~~~~~~~^^^^^^^^^^^^^^
_mysql_connector.MySQLInterfaceError: Access denied for user 'root'@'localhost' (using password: YES)

The above exception was the direct cause of the following exception:

Traceback (most recent call last):
  File "/Users/paulrichardmunozbruno/Desktop/proyecto tecnicas de programacion/Gestion_Alimentos.py", line 221, in connect
    self.conn = mysql.connector.connect(
                ~~~~~~~~~~~~~~~~~~~~~~~^
        host=config['db_host'],
        ^^^^^^^^^^^^^^^^^^^^^^^
    ...<5 lines>...
        autocommit=False  # Control manual de transacciones
        ^^^^^^^^^^^^^^^^^^^^^^^^^^^^^^^^^^^^^^^^^^^^^^^^^^^
    )
    ^
  File "/Users/paulrichardmunozbruno/Library/Python/3.14/lib/python/site-packages/mysql/connector/pooling.py", line 322, in connect
    return CMySQLConnection(*args, **kwargs)
  File "/Users/paulrichardmunozbruno/Library/Python/3.14/lib/python/site-packages/mysql/connector/connection_cext.py", line 142, in __init__
    self.connect(**kwargs)
    ~~~~~~~~~~~~^^^^^^^^^^
  File "/Users/paulrichardmunozbruno/Library/Python/3.14/lib/python/site-packages/mysql/connector/abstracts.py", line 1604, in connect
    self._open_connection()
    ~~~~~~~~~~~~~~~~~~~~~^^
  File "/Users/paulrichardmunozbruno/Library/Python/3.14/lib/python/site-packages/mysql/connector/connection_cext.py", line 360, in _open_connection
    raise get_mysql_exception(
        err.errno, msg=err.msg, sqlstate=err.sqlstate
    ) from err
mysql.connector.errors.ProgrammingError: 1045 (28000): Access denied for user 'root'@'localhost' (using password: YES)

During handling of the above exception, another exception occurred:

Traceback (most recent call last):
  File "/Users/paulrichardmunozbruno/Desktop/proyecto tecnicas de programacion/Gestion_Alimentos.py", line 257, in execute_query
    conn = self.connect()
  File "/Users/paulrichardmunozbruno/Desktop/proyecto tecnicas de programacion/Gestion_Alimentos.py", line 244, in connect
    raise DatabaseError(error_message)
DatabaseError: Error al conectar con la base de datos (intento 1): 1045 (28000): Access denied for user 'root'@'localhost' (using password: YES)

2025-10-29 22:06:49,719 - root - ERROR - Error en la BD durante la inicialización de usuarios: Error inesperado: Error al conectar con la base de datos (intento 1): 1045 (28000): Access denied for user 'root'@'localhost' (using password: YES). La tabla 'usuarios' podría no existir.
2025-10-29 22:07:05,115 - root - ERROR - Error al conectar con la base de datos (intento 2): 1045 (28000): Access denied for user 'root'@'localhost' (using password: YES)
2025-10-29 22:07:05,117 - root - ERROR - Error inesperado en execute_query: Traceback (most recent call last):
  File "/Users/paulrichardmunozbruno/Library/Python/3.14/lib/python/site-packages/mysql/connector/connection_cext.py", line 354, in _open_connection
    self._cmysql.connect(**cnx_kwargs)
    ~~~~~~~~~~~~~~~~~~~~^^^^^^^^^^^^^^
_mysql_connector.MySQLInterfaceError: Access denied for user 'root'@'localhost' (using password: YES)

The above exception was the direct cause of the following exception:

Traceback (most recent call last):
  File "/Users/paulrichardmunozbruno/Desktop/proyecto tecnicas de programacion/Gestion_Alimentos.py", line 221, in connect
    self.conn = mysql.connector.connect(
                ~~~~~~~~~~~~~~~~~~~~~~~^
        host=config['db_host'],
        ^^^^^^^^^^^^^^^^^^^^^^^
    ...<5 lines>...
        autocommit=False  # Control manual de transacciones
        ^^^^^^^^^^^^^^^^^^^^^^^^^^^^^^^^^^^^^^^^^^^^^^^^^^^
    )
    ^
  File "/Users/paulrichardmunozbruno/Library/Python/3.14/lib/python/site-packages/mysql/connector/pooling.py", line 322, in connect
    return CMySQLConnection(*args, **kwargs)
  File "/Users/paulrichardmunozbruno/Library/Python/3.14/lib/python/site-packages/mysql/connector/connection_cext.py", line 142, in __init__
    self.connect(**kwargs)
    ~~~~~~~~~~~~^^^^^^^^^^
  File "/Users/paulrichardmunozbruno/Library/Python/3.14/lib/python/site-packages/mysql/connector/abstracts.py", line 1604, in connect
    self._open_connection()
    ~~~~~~~~~~~~~~~~~~~~~^^
  File "/Users/paulrichardmunozbruno/Library/Python/3.14/lib/python/site-packages/mysql/connector/connection_cext.py", line 360, in _open_connection
    raise get_mysql_exception(
        err.errno, msg=err.msg, sqlstate=err.sqlstate
    ) from err
mysql.connector.errors.ProgrammingError: 1045 (28000): Access denied for user 'root'@'localhost' (using password: YES)

During handling of the above exception, another exception occurred:

Traceback (most recent call last):
  File "/Users/paulrichardmunozbruno/Desktop/proyecto tecnicas de programacion/Gestion_Alimentos.py", line 257, in execute_query
    conn = self.connect()
  File "/Users/paulrichardmunozbruno/Desktop/proyecto tecnicas de programacion/Gestion_Alimentos.py", line 244, in connect
    raise DatabaseError(error_message)
DatabaseError: Error al conectar con la base de datos (intento 2): 1045 (28000): Access denied for user 'root'@'localhost' (using password: YES)

2025-10-29 22:07:05,117 - root - ERROR - Error de BD en login_user: Error inesperado: Error al conectar con la base de datos (intento 2): 1045 (28000): Access denied for user 'root'@'localhost' (using password: YES)
2025-10-29 22:07:07,798 - root - ERROR - Error al conectar con la base de datos (intento 3): 1045 (28000): Access denied for user 'root'@'localhost' (using password: YES)
2025-10-29 22:07:07,800 - root - ERROR - Error inesperado en execute_query: Traceback (most recent call last):
  File "/Users/paulrichardmunozbruno/Library/Python/3.14/lib/python/site-packages/mysql/connector/connection_cext.py", line 354, in _open_connection
    self._cmysql.connect(**cnx_kwargs)
    ~~~~~~~~~~~~~~~~~~~~^^^^^^^^^^^^^^
_mysql_connector.MySQLInterfaceError: Access denied for user 'root'@'localhost' (using password: YES)

The above exception was the direct cause of the following exception:

Traceback (most recent call last):
  File "/Users/paulrichardmunozbruno/Desktop/proyecto tecnicas de programacion/Gestion_Alimentos.py", line 221, in connect
    self.conn = mysql.connector.connect(
                ~~~~~~~~~~~~~~~~~~~~~~~^
        host=config['db_host'],
        ^^^^^^^^^^^^^^^^^^^^^^^
    ...<5 lines>...
        autocommit=False  # Control manual de transacciones
        ^^^^^^^^^^^^^^^^^^^^^^^^^^^^^^^^^^^^^^^^^^^^^^^^^^^
    )
    ^
  File "/Users/paulrichardmunozbruno/Library/Python/3.14/lib/python/site-packages/mysql/connector/pooling.py", line 322, in connect
    return CMySQLConnection(*args, **kwargs)
  File "/Users/paulrichardmunozbruno/Library/Python/3.14/lib/python/site-packages/mysql/connector/connection_cext.py", line 142, in __init__
    self.connect(**kwargs)
    ~~~~~~~~~~~~^^^^^^^^^^
  File "/Users/paulrichardmunozbruno/Library/Python/3.14/lib/python/site-packages/mysql/connector/abstracts.py", line 1604, in connect
    self._open_connection()
    ~~~~~~~~~~~~~~~~~~~~~^^
  File "/Users/paulrichardmunozbruno/Library/Python/3.14/lib/python/site-packages/mysql/connector/connection_cext.py", line 360, in _open_connection
    raise get_mysql_exception(
        err.errno, msg=err.msg, sqlstate=err.sqlstate
    ) from err
mysql.connector.errors.ProgrammingError: 1045 (28000): Access denied for user 'root'@'localhost' (using password: YES)

During handling of the above exception, another exception occurred:

Traceback (most recent call last):
  File "/Users/paulrichardmunozbruno/Desktop/proyecto tecnicas de programacion/Gestion_Alimentos.py", line 257, in execute_query
    conn = self.connect()
  File "/Users/paulrichardmunozbruno/Desktop/proyecto tecnicas de programacion/Gestion_Alimentos.py", line 241, in connect
    raise DatabaseError(f"No se pudo conectar después de {self.max_attempts} intentos: {e}")
DatabaseError: No se pudo conectar después de 3 intentos: 1045 (28000): Access denied for user 'root'@'localhost' (using password: YES)

2025-10-29 22:07:07,801 - root - ERROR - Error de BD en login_user: Error inesperado: No se pudo conectar después de 3 intentos: 1045 (28000): Access denied for user 'root'@'localhost' (using password: YES)
2025-10-29 22:07:12,025 - root - INFO - Aplicación cerrada por el usuario
2025-10-29 22:08:15,537 - root - ERROR - Error al conectar con la base de datos (intento 1): 1045 (28000): Access denied for user 'root'@'localhost' (using password: YES)
2025-10-29 22:08:15,538 - root - ERROR - Error inesperado en execute_query: Traceback (most recent call last):
  File "/Users/paulrichardmunozbruno/Library/Python/3.14/lib/python/site-packages/mysql/connector/connection_cext.py", line 354, in _open_connection
    self._cmysql.connect(**cnx_kwargs)
    ~~~~~~~~~~~~~~~~~~~~^^^^^^^^^^^^^^
_mysql_connector.MySQLInterfaceError: Access denied for user 'root'@'localhost' (using password: YES)

The above exception was the direct cause of the following exception:

Traceback (most recent call last):
  File "/Users/paulrichardmunozbruno/Desktop/proyecto tecnicas de programacion/Gestion_Alimentos.py", line 221, in connect
    self.conn = mysql.connector.connect(
                ~~~~~~~~~~~~~~~~~~~~~~~^
        host=config['db_host'],
        ^^^^^^^^^^^^^^^^^^^^^^^
    ...<5 lines>...
        autocommit=False  # Control manual de transacciones
        ^^^^^^^^^^^^^^^^^^^^^^^^^^^^^^^^^^^^^^^^^^^^^^^^^^^
    )
    ^
  File "/Users/paulrichardmunozbruno/Library/Python/3.14/lib/python/site-packages/mysql/connector/pooling.py", line 322, in connect
    return CMySQLConnection(*args, **kwargs)
  File "/Users/paulrichardmunozbruno/Library/Python/3.14/lib/python/site-packages/mysql/connector/connection_cext.py", line 142, in __init__
    self.connect(**kwargs)
    ~~~~~~~~~~~~^^^^^^^^^^
  File "/Users/paulrichardmunozbruno/Library/Python/3.14/lib/python/site-packages/mysql/connector/abstracts.py", line 1604, in connect
    self._open_connection()
    ~~~~~~~~~~~~~~~~~~~~~^^
  File "/Users/paulrichardmunozbruno/Library/Python/3.14/lib/python/site-packages/mysql/connector/connection_cext.py", line 360, in _open_connection
    raise get_mysql_exception(
        err.errno, msg=err.msg, sqlstate=err.sqlstate
    ) from err
mysql.connector.errors.ProgrammingError: 1045 (28000): Access denied for user 'root'@'localhost' (using password: YES)

During handling of the above exception, another exception occurred:

Traceback (most recent call last):
  File "/Users/paulrichardmunozbruno/Desktop/proyecto tecnicas de programacion/Gestion_Alimentos.py", line 257, in execute_query
    conn = self.connect()
  File "/Users/paulrichardmunozbruno/Desktop/proyecto tecnicas de programacion/Gestion_Alimentos.py", line 244, in connect
    raise DatabaseError(error_message)
DatabaseError: Error al conectar con la base de datos (intento 1): 1045 (28000): Access denied for user 'root'@'localhost' (using password: YES)

2025-10-29 22:08:15,538 - root - ERROR - Error en la BD durante la inicialización de usuarios: Error inesperado: Error al conectar con la base de datos (intento 1): 1045 (28000): Access denied for user 'root'@'localhost' (using password: YES). La tabla 'usuarios' podría no existir.
2025-10-29 22:08:26,783 - root - ERROR - Error al conectar con la base de datos (intento 2): 1045 (28000): Access denied for user 'root'@'localhost' (using password: YES)
2025-10-29 22:08:26,786 - root - ERROR - Error inesperado en execute_query: Traceback (most recent call last):
  File "/Users/paulrichardmunozbruno/Library/Python/3.14/lib/python/site-packages/mysql/connector/connection_cext.py", line 354, in _open_connection
    self._cmysql.connect(**cnx_kwargs)
    ~~~~~~~~~~~~~~~~~~~~^^^^^^^^^^^^^^
_mysql_connector.MySQLInterfaceError: Access denied for user 'root'@'localhost' (using password: YES)

The above exception was the direct cause of the following exception:

Traceback (most recent call last):
  File "/Users/paulrichardmunozbruno/Desktop/proyecto tecnicas de programacion/Gestion_Alimentos.py", line 221, in connect
    self.conn = mysql.connector.connect(
                ~~~~~~~~~~~~~~~~~~~~~~~^
        host=config['db_host'],
        ^^^^^^^^^^^^^^^^^^^^^^^
    ...<5 lines>...
        autocommit=False  # Control manual de transacciones
        ^^^^^^^^^^^^^^^^^^^^^^^^^^^^^^^^^^^^^^^^^^^^^^^^^^^
    )
    ^
  File "/Users/paulrichardmunozbruno/Library/Python/3.14/lib/python/site-packages/mysql/connector/pooling.py", line 322, in connect
    return CMySQLConnection(*args, **kwargs)
  File "/Users/paulrichardmunozbruno/Library/Python/3.14/lib/python/site-packages/mysql/connector/connection_cext.py", line 142, in __init__
    self.connect(**kwargs)
    ~~~~~~~~~~~~^^^^^^^^^^
  File "/Users/paulrichardmunozbruno/Library/Python/3.14/lib/python/site-packages/mysql/connector/abstracts.py", line 1604, in connect
    self._open_connection()
    ~~~~~~~~~~~~~~~~~~~~~^^
  File "/Users/paulrichardmunozbruno/Library/Python/3.14/lib/python/site-packages/mysql/connector/connection_cext.py", line 360, in _open_connection
    raise get_mysql_exception(
        err.errno, msg=err.msg, sqlstate=err.sqlstate
    ) from err
mysql.connector.errors.ProgrammingError: 1045 (28000): Access denied for user 'root'@'localhost' (using password: YES)

During handling of the above exception, another exception occurred:

Traceback (most recent call last):
  File "/Users/paulrichardmunozbruno/Desktop/proyecto tecnicas de programacion/Gestion_Alimentos.py", line 257, in execute_query
    conn = self.connect()
  File "/Users/paulrichardmunozbruno/Desktop/proyecto tecnicas de programacion/Gestion_Alimentos.py", line 244, in connect
    raise DatabaseError(error_message)
DatabaseError: Error al conectar con la base de datos (intento 2): 1045 (28000): Access denied for user 'root'@'localhost' (using password: YES)

2025-10-29 22:08:26,786 - root - ERROR - Error de BD en login_user: Error inesperado: Error al conectar con la base de datos (intento 2): 1045 (28000): Access denied for user 'root'@'localhost' (using password: YES)
2025-10-29 22:10:05,074 - root - INFO - Conexión a la base de datos establecida correctamente.
2025-10-29 22:10:14,020 - root - WARNING - Contraseña incorrecta para: paul
2025-10-29 22:10:32,870 - root - INFO - Aplicación cerrada por el usuario
2025-10-29 22:10:32,871 - root - INFO - Conexión a la base de datos cerrada.
2025-10-29 22:11:17,771 - root - INFO - Conexión a la base de datos establecida correctamente.
2025-10-29 22:11:17,771 - root - WARNING - No se encontraron usuarios. Inicializando usuarios por defecto...
2025-10-29 22:11:17,772 - root - INFO - Se insertaron 9 usuarios por defecto correctamente.
2025-10-29 22:11:26,643 - root - WARNING - Contraseña incorrecta para: paul
2025-10-29 22:12:59,450 - root - INFO - Aplicación cerrada por el usuario
2025-10-29 22:12:59,450 - root - INFO - Conexión a la base de datos cerrada.
2025-10-29 22:13:04,742 - root - INFO - Aplicación cerrada por el usuario
2025-10-29 22:13:23,193 - root - INFO - Conexión a la base de datos establecida correctamente.
2025-10-29 22:13:34,316 - root - WARNING - Contraseña incorrecta para: paul
2025-10-29 22:13:38,218 - root - INFO - Aplicación cerrada por el usuario
2025-10-29 22:13:38,219 - root - INFO - Conexión a la base de datos cerrada.
2025-10-29 22:13:45,213 - root - INFO - Conexión a la base de datos establecida correctamente.
2025-10-29 22:13:55,968 - root - WARNING - Contraseña incorrecta para: paul
2025-10-29 22:15:47,839 - root - INFO - Aplicación cerrada por el usuario
2025-10-29 22:15:47,840 - root - INFO - Conexión a la base de datos cerrada.
2025-10-29 22:15:49,492 - root - INFO - Conexión a la base de datos establecida correctamente.
2025-10-29 22:15:58,644 - root - WARNING - Contraseña incorrecta para: paul
2025-10-29 22:16:10,927 - root - INFO - Aplicación cerrada por el usuario
2025-10-29 22:16:10,928 - root - INFO - Conexión a la base de datos cerrada.
2025-10-29 22:16:39,994 - root - INFO - Conexión a la base de datos establecida correctamente.
2025-10-29 22:16:50,445 - root - WARNING - Contraseña incorrecta para: paul
2025-10-29 22:19:49,860 - root - INFO - Conexión a la base de datos establecida correctamente.
2025-10-29 22:20:03,463 - root - WARNING - Contraseña incorrecta para: paul
2025-10-29 22:20:14,383 - root - WARNING - Contraseña incorrecta para: paul
2025-10-29 22:20:20,295 - root - INFO - Aplicación cerrada por el usuario
2025-10-29 22:20:20,296 - root - INFO - Conexión a la base de datos cerrada.
2025-10-29 22:20:43,816 - root - INFO - Aplicación cerrada por el usuario
2025-10-29 22:20:43,816 - root - INFO - Conexión a la base de datos cerrada.
2025-10-29 22:22:13,279 - root - INFO - Conexión a la base de datos establecida correctamente.
2025-10-29 22:22:25,551 - root - WARNING - Contraseña incorrecta para: paul
2025-10-29 22:24:05,935 - root - WARNING - Contraseña incorrecta para: paul
2025-10-29 22:24:28,809 - root - WARNING - Contraseña incorrecta para: paul
2025-10-29 22:30:29,887 - root - INFO - Aplicación cerrada por el usuario
2025-10-29 22:30:29,889 - root - INFO - Conexión a la base de datos cerrada.
2025-10-29 22:33:25,936 - root - INFO - Conexión a la base de datos establecida correctamente.
2025-10-29 22:33:37,314 - root - INFO - Login exitoso para: paul (admin)
2025-10-29 22:33:41,173 - root - ERROR - Error al cargar datos del dashboard: 'NoneType' object has no attribute 'setText'
2025-10-29 22:33:56,186 - root - CRITICAL - Error crítico al iniciar la aplicación: Traceback (most recent call last):
  File "/Users/paulrichardmunozbruno/Desktop/proyecto tecnicas de programacion/Gestion_Alimentos.py", line 3065, in run
    main_window = ModernMainWindow(
        self.business_logic,
    ...<3 lines>...
        self.config_manager
    )
  File "/Users/paulrichardmunozbruno/Desktop/proyecto tecnicas de programacion/Gestion_Alimentos.py", line 2768, in __init__
    self.setup_tabs()
    ~~~~~~~~~~~~~~~^^
  File "/Users/paulrichardmunozbruno/Desktop/proyecto tecnicas de programacion/Gestion_Alimentos.py", line 2865, in setup_tabs
    proveedores_panel = ProveedoresManagementPanel(self.business_logic, self.user_role)
  File "/Users/paulrichardmunozbruno/Desktop/proyecto tecnicas de programacion/Gestion_Alimentos.py", line 1306, in __init__
    self.setup_ui()
    ~~~~~~~~~~~~~^^
  File "/Users/paulrichardmunozbruno/Desktop/proyecto tecnicas de programacion/Gestion_Alimentos.py", line 1377, in setup_ui
    self.ruc_input.setValidator(QIntValidator(0, 99999999999))
                                ~~~~~~~~~~~~~^^^^^^^^^^^^^^^^
OverflowError: argument 2 overflowed: value must be in the range -2147483648 to 2147483647

2025-10-29 22:35:10,836 - root - INFO - Conexión a la base de datos cerrada.
2025-10-29 22:38:56,027 - root - INFO - Conexión a la base de datos establecida correctamente.
2025-10-29 22:39:07,430 - root - INFO - Login exitoso para: paul (admin)
2025-10-29 22:39:07,516 - root - ERROR - Error al cargar datos del dashboard: 'NoneType' object has no attribute 'setText'
2025-10-29 22:39:16,113 - root - INFO - Aplicación iniciada correctamente
2025-10-29 22:40:13,474 - root - ERROR - Error al cargar datos del dashboard: 'NoneType' object has no attribute 'setText'
2025-10-29 22:40:16,407 - root - ERROR - Error al cargar datos del dashboard: 'NoneType' object has no attribute 'setText'
2025-10-29 22:40:56,735 - root - INFO - Conexión a la base de datos cerrada.
2025-10-30 10:00:18,505 - root - INFO - Conexión a la base de datos establecida correctamente.
2025-10-30 10:00:50,809 - root - INFO - Login exitoso para: paul (admin)
2025-10-30 10:00:50,822 - root - CRITICAL - Error crítico al iniciar la aplicación: Traceback (most recent call last):
  File "/Users/paulrichardmunozbruno/Desktop/proyecto tecnicas de programacion/Gestion_Alimentos.py", line 3069, in run
    main_window = ModernMainWindow(
        self.business_logic,
    ...<3 lines>...
        self.config_manager
    )
  File "/Users/paulrichardmunozbruno/Desktop/proyecto tecnicas de programacion/Gestion_Alimentos.py", line 2772, in __init__
    self.setup_tabs()
    ~~~~~~~~~~~~~~~^^
  File "/Users/paulrichardmunozbruno/Desktop/proyecto tecnicas de programacion/Gestion_Alimentos.py", line 2859, in setup_tabs
    dashboard_panel = DashboardPanel(self.business_logic)
  File "/Users/paulrichardmunozbruno/Desktop/proyecto tecnicas de programacion/Gestion_Alimentos.py", line 2229, in __init__
    self.setup_ui()
    ~~~~~~~~~~~~~^^
  File "/Users/paulrichardmunozbruno/Desktop/proyecto tecnicas de programacion/Gestion_Alimentos.py", line 2257, in setup_ui
    card = self._create_stat_card(title, icon)
TypeError: DashboardPanel._create_stat_card() missing 1 required positional argument: 'icon'

2025-10-30 10:01:02,792 - root - INFO - Conexión a la base de datos cerrada.
2025-10-30 10:02:35,311 - root - INFO - Conexión a la base de datos establecida correctamente.
2025-10-30 10:02:47,222 - root - INFO - Login exitoso para: paul (admin)
2025-10-30 10:11:38,100 - root - INFO - Aplicación iniciada correctamente
2025-10-30 10:12:19,686 - root - INFO - Conexión a la base de datos cerrada.
2025-10-30 10:18:17,879 - root - ERROR - Error al conectar con la base de datos (intento 1): 1045 (28000): Access denied for user 'root'@'localhost' (using password: YES)
2025-10-30 10:18:17,881 - root - ERROR - Error inesperado en execute_query: Traceback (most recent call last):
  File "/Users/paulrichardmunozbruno/Library/Python/3.14/lib/python/site-packages/mysql/connector/connection_cext.py", line 354, in _open_connection
    self._cmysql.connect(**cnx_kwargs)
    ~~~~~~~~~~~~~~~~~~~~^^^^^^^^^^^^^^
_mysql_connector.MySQLInterfaceError: Access denied for user 'root'@'localhost' (using password: YES)

The above exception was the direct cause of the following exception:

Traceback (most recent call last):
  File "/Users/paulrichardmunozbruno/Desktop/proyecto tecnicas de programacion/Gestion_Alimentos.py", line 224, in connect
    self.conn = mysql.connector.connect(
                ~~~~~~~~~~~~~~~~~~~~~~~^
        host=config['db_host'],
        ^^^^^^^^^^^^^^^^^^^^^^^
    ...<6 lines>...
        auth_plugin='mysql_native_password'  # Plugin de autenticación explícito
        ^^^^^^^^^^^^^^^^^^^^^^^^^^^^^^^^^^^^^^^^^^^^^^^^^^^^^^^^^^^^^^^^^^^^^^^^
    )
    ^
  File "/Users/paulrichardmunozbruno/Library/Python/3.14/lib/python/site-packages/mysql/connector/pooling.py", line 322, in connect
    return CMySQLConnection(*args, **kwargs)
  File "/Users/paulrichardmunozbruno/Library/Python/3.14/lib/python/site-packages/mysql/connector/connection_cext.py", line 142, in __init__
    self.connect(**kwargs)
    ~~~~~~~~~~~~^^^^^^^^^^
  File "/Users/paulrichardmunozbruno/Library/Python/3.14/lib/python/site-packages/mysql/connector/abstracts.py", line 1604, in connect
    self._open_connection()
    ~~~~~~~~~~~~~~~~~~~~~^^
  File "/Users/paulrichardmunozbruno/Library/Python/3.14/lib/python/site-packages/mysql/connector/connection_cext.py", line 360, in _open_connection
    raise get_mysql_exception(
        err.errno, msg=err.msg, sqlstate=err.sqlstate
    ) from err
mysql.connector.errors.ProgrammingError: 1045 (28000): Access denied for user 'root'@'localhost' (using password: YES)

During handling of the above exception, another exception occurred:

Traceback (most recent call last):
  File "/Users/paulrichardmunozbruno/Desktop/proyecto tecnicas de programacion/Gestion_Alimentos.py", line 261, in execute_query
    conn = self.connect()
  File "/Users/paulrichardmunozbruno/Desktop/proyecto tecnicas de programacion/Gestion_Alimentos.py", line 248, in connect
    raise DatabaseError(error_message)
DatabaseError: Error al conectar con la base de datos (intento 1): 1045 (28000): Access denied for user 'root'@'localhost' (using password: YES)

2025-10-30 10:18:17,881 - root - ERROR - Error en la BD durante la inicialización de usuarios: Error inesperado: Error al conectar con la base de datos (intento 1): 1045 (28000): Access denied for user 'root'@'localhost' (using password: YES). La tabla 'usuarios' podría no existir.
2025-10-30 10:18:31,612 - root - ERROR - Error al conectar con la base de datos (intento 2): 1045 (28000): Access denied for user 'root'@'localhost' (using password: YES)
2025-10-30 10:18:31,614 - root - ERROR - Error inesperado en execute_query: Traceback (most recent call last):
  File "/Users/paulrichardmunozbruno/Library/Python/3.14/lib/python/site-packages/mysql/connector/connection_cext.py", line 354, in _open_connection
    self._cmysql.connect(**cnx_kwargs)
    ~~~~~~~~~~~~~~~~~~~~^^^^^^^^^^^^^^
_mysql_connector.MySQLInterfaceError: Access denied for user 'root'@'localhost' (using password: YES)

The above exception was the direct cause of the following exception:

Traceback (most recent call last):
  File "/Users/paulrichardmunozbruno/Desktop/proyecto tecnicas de programacion/Gestion_Alimentos.py", line 224, in connect
    self.conn = mysql.connector.connect(
                ~~~~~~~~~~~~~~~~~~~~~~~^
        host=config['db_host'],
        ^^^^^^^^^^^^^^^^^^^^^^^
    ...<6 lines>...
        auth_plugin='mysql_native_password'  # Plugin de autenticación explícito
        ^^^^^^^^^^^^^^^^^^^^^^^^^^^^^^^^^^^^^^^^^^^^^^^^^^^^^^^^^^^^^^^^^^^^^^^^
    )
    ^
  File "/Users/paulrichardmunozbruno/Library/Python/3.14/lib/python/site-packages/mysql/connector/pooling.py", line 322, in connect
    return CMySQLConnection(*args, **kwargs)
  File "/Users/paulrichardmunozbruno/Library/Python/3.14/lib/python/site-packages/mysql/connector/connection_cext.py", line 142, in __init__
    self.connect(**kwargs)
    ~~~~~~~~~~~~^^^^^^^^^^
  File "/Users/paulrichardmunozbruno/Library/Python/3.14/lib/python/site-packages/mysql/connector/abstracts.py", line 1604, in connect
    self._open_connection()
    ~~~~~~~~~~~~~~~~~~~~~^^
  File "/Users/paulrichardmunozbruno/Library/Python/3.14/lib/python/site-packages/mysql/connector/connection_cext.py", line 360, in _open_connection
    raise get_mysql_exception(
        err.errno, msg=err.msg, sqlstate=err.sqlstate
    ) from err
mysql.connector.errors.ProgrammingError: 1045 (28000): Access denied for user 'root'@'localhost' (using password: YES)

During handling of the above exception, another exception occurred:

Traceback (most recent call last):
  File "/Users/paulrichardmunozbruno/Desktop/proyecto tecnicas de programacion/Gestion_Alimentos.py", line 261, in execute_query
    conn = self.connect()
  File "/Users/paulrichardmunozbruno/Desktop/proyecto tecnicas de programacion/Gestion_Alimentos.py", line 248, in connect
    raise DatabaseError(error_message)
DatabaseError: Error al conectar con la base de datos (intento 2): 1045 (28000): Access denied for user 'root'@'localhost' (using password: YES)

2025-10-30 10:18:31,614 - root - ERROR - Error de BD en login_user: Error inesperado: Error al conectar con la base de datos (intento 2): 1045 (28000): Access denied for user 'root'@'localhost' (using password: YES)
2025-10-30 10:18:39,721 - root - INFO - Aplicación cerrada por el usuario
2025-10-30 10:19:09,428 - root - ERROR - Error al conectar con la base de datos (intento 1): 1045 (28000): Access denied for user 'root'@'localhost' (using password: YES)
2025-10-30 10:19:09,430 - root - ERROR - Error inesperado en execute_query: Traceback (most recent call last):
  File "/Users/paulrichardmunozbruno/Library/Python/3.14/lib/python/site-packages/mysql/connector/connection_cext.py", line 354, in _open_connection
    self._cmysql.connect(**cnx_kwargs)
    ~~~~~~~~~~~~~~~~~~~~^^^^^^^^^^^^^^
_mysql_connector.MySQLInterfaceError: Access denied for user 'root'@'localhost' (using password: YES)

The above exception was the direct cause of the following exception:

Traceback (most recent call last):
  File "/Users/paulrichardmunozbruno/Desktop/proyecto tecnicas de programacion/Gestion_Alimentos.py", line 224, in connect
    self.conn = mysql.connector.connect(
                ~~~~~~~~~~~~~~~~~~~~~~~^
        host=config['db_host'],
        ^^^^^^^^^^^^^^^^^^^^^^^
    ...<6 lines>...
        auth_plugin='mysql_native_password'  # Plugin de autenticación explícito
        ^^^^^^^^^^^^^^^^^^^^^^^^^^^^^^^^^^^^^^^^^^^^^^^^^^^^^^^^^^^^^^^^^^^^^^^^
    )
    ^
  File "/Users/paulrichardmunozbruno/Library/Python/3.14/lib/python/site-packages/mysql/connector/pooling.py", line 322, in connect
    return CMySQLConnection(*args, **kwargs)
  File "/Users/paulrichardmunozbruno/Library/Python/3.14/lib/python/site-packages/mysql/connector/connection_cext.py", line 142, in __init__
    self.connect(**kwargs)
    ~~~~~~~~~~~~^^^^^^^^^^
  File "/Users/paulrichardmunozbruno/Library/Python/3.14/lib/python/site-packages/mysql/connector/abstracts.py", line 1604, in connect
    self._open_connection()
    ~~~~~~~~~~~~~~~~~~~~~^^
  File "/Users/paulrichardmunozbruno/Library/Python/3.14/lib/python/site-packages/mysql/connector/connection_cext.py", line 360, in _open_connection
    raise get_mysql_exception(
        err.errno, msg=err.msg, sqlstate=err.sqlstate
    ) from err
mysql.connector.errors.ProgrammingError: 1045 (28000): Access denied for user 'root'@'localhost' (using password: YES)

During handling of the above exception, another exception occurred:

Traceback (most recent call last):
  File "/Users/paulrichardmunozbruno/Desktop/proyecto tecnicas de programacion/Gestion_Alimentos.py", line 261, in execute_query
    conn = self.connect()
  File "/Users/paulrichardmunozbruno/Desktop/proyecto tecnicas de programacion/Gestion_Alimentos.py", line 248, in connect
    raise DatabaseError(error_message)
DatabaseError: Error al conectar con la base de datos (intento 1): 1045 (28000): Access denied for user 'root'@'localhost' (using password: YES)

2025-10-30 10:19:09,430 - root - ERROR - Error en la BD durante la inicialización de usuarios: Error inesperado: Error al conectar con la base de datos (intento 1): 1045 (28000): Access denied for user 'root'@'localhost' (using password: YES). La tabla 'usuarios' podría no existir.
2025-10-30 10:19:16,626 - root - ERROR - Error al conectar con la base de datos (intento 2): 1045 (28000): Access denied for user 'root'@'localhost' (using password: YES)
2025-10-30 10:19:16,628 - root - ERROR - Error inesperado en execute_query: Traceback (most recent call last):
  File "/Users/paulrichardmunozbruno/Library/Python/3.14/lib/python/site-packages/mysql/connector/connection_cext.py", line 354, in _open_connection
    self._cmysql.connect(**cnx_kwargs)
    ~~~~~~~~~~~~~~~~~~~~^^^^^^^^^^^^^^
_mysql_connector.MySQLInterfaceError: Access denied for user 'root'@'localhost' (using password: YES)

The above exception was the direct cause of the following exception:

Traceback (most recent call last):
  File "/Users/paulrichardmunozbruno/Desktop/proyecto tecnicas de programacion/Gestion_Alimentos.py", line 224, in connect
    self.conn = mysql.connector.connect(
                ~~~~~~~~~~~~~~~~~~~~~~~^
        host=config['db_host'],
        ^^^^^^^^^^^^^^^^^^^^^^^
    ...<6 lines>...
        auth_plugin='mysql_native_password'  # Plugin de autenticación explícito
        ^^^^^^^^^^^^^^^^^^^^^^^^^^^^^^^^^^^^^^^^^^^^^^^^^^^^^^^^^^^^^^^^^^^^^^^^
    )
    ^
  File "/Users/paulrichardmunozbruno/Library/Python/3.14/lib/python/site-packages/mysql/connector/pooling.py", line 322, in connect
    return CMySQLConnection(*args, **kwargs)
  File "/Users/paulrichardmunozbruno/Library/Python/3.14/lib/python/site-packages/mysql/connector/connection_cext.py", line 142, in __init__
    self.connect(**kwargs)
    ~~~~~~~~~~~~^^^^^^^^^^
  File "/Users/paulrichardmunozbruno/Library/Python/3.14/lib/python/site-packages/mysql/connector/abstracts.py", line 1604, in connect
    self._open_connection()
    ~~~~~~~~~~~~~~~~~~~~~^^
  File "/Users/paulrichardmunozbruno/Library/Python/3.14/lib/python/site-packages/mysql/connector/connection_cext.py", line 360, in _open_connection
    raise get_mysql_exception(
        err.errno, msg=err.msg, sqlstate=err.sqlstate
    ) from err
mysql.connector.errors.ProgrammingError: 1045 (28000): Access denied for user 'root'@'localhost' (using password: YES)

During handling of the above exception, another exception occurred:

Traceback (most recent call last):
  File "/Users/paulrichardmunozbruno/Desktop/proyecto tecnicas de programacion/Gestion_Alimentos.py", line 261, in execute_query
    conn = self.connect()
  File "/Users/paulrichardmunozbruno/Desktop/proyecto tecnicas de programacion/Gestion_Alimentos.py", line 248, in connect
    raise DatabaseError(error_message)
DatabaseError: Error al conectar con la base de datos (intento 2): 1045 (28000): Access denied for user 'root'@'localhost' (using password: YES)

2025-10-30 10:19:16,628 - root - ERROR - Error de BD en login_user: Error inesperado: Error al conectar con la base de datos (intento 2): 1045 (28000): Access denied for user 'root'@'localhost' (using password: YES)
2025-10-30 10:19:24,141 - root - ERROR - Error al conectar con la base de datos (intento 3): 1045 (28000): Access denied for user 'root'@'localhost' (using password: YES)
2025-10-30 10:19:24,143 - root - ERROR - Error inesperado en execute_query: Traceback (most recent call last):
  File "/Users/paulrichardmunozbruno/Library/Python/3.14/lib/python/site-packages/mysql/connector/connection_cext.py", line 354, in _open_connection
    self._cmysql.connect(**cnx_kwargs)
    ~~~~~~~~~~~~~~~~~~~~^^^^^^^^^^^^^^
_mysql_connector.MySQLInterfaceError: Access denied for user 'root'@'localhost' (using password: YES)

The above exception was the direct cause of the following exception:

Traceback (most recent call last):
  File "/Users/paulrichardmunozbruno/Desktop/proyecto tecnicas de programacion/Gestion_Alimentos.py", line 224, in connect
    self.conn = mysql.connector.connect(
                ~~~~~~~~~~~~~~~~~~~~~~~^
        host=config['db_host'],
        ^^^^^^^^^^^^^^^^^^^^^^^
    ...<6 lines>...
        auth_plugin='mysql_native_password'  # Plugin de autenticación explícito
        ^^^^^^^^^^^^^^^^^^^^^^^^^^^^^^^^^^^^^^^^^^^^^^^^^^^^^^^^^^^^^^^^^^^^^^^^
    )
    ^
  File "/Users/paulrichardmunozbruno/Library/Python/3.14/lib/python/site-packages/mysql/connector/pooling.py", line 322, in connect
    return CMySQLConnection(*args, **kwargs)
  File "/Users/paulrichardmunozbruno/Library/Python/3.14/lib/python/site-packages/mysql/connector/connection_cext.py", line 142, in __init__
    self.connect(**kwargs)
    ~~~~~~~~~~~~^^^^^^^^^^
  File "/Users/paulrichardmunozbruno/Library/Python/3.14/lib/python/site-packages/mysql/connector/abstracts.py", line 1604, in connect
    self._open_connection()
    ~~~~~~~~~~~~~~~~~~~~~^^
  File "/Users/paulrichardmunozbruno/Library/Python/3.14/lib/python/site-packages/mysql/connector/connection_cext.py", line 360, in _open_connection
    raise get_mysql_exception(
        err.errno, msg=err.msg, sqlstate=err.sqlstate
    ) from err
mysql.connector.errors.ProgrammingError: 1045 (28000): Access denied for user 'root'@'localhost' (using password: YES)

During handling of the above exception, another exception occurred:

Traceback (most recent call last):
  File "/Users/paulrichardmunozbruno/Desktop/proyecto tecnicas de programacion/Gestion_Alimentos.py", line 261, in execute_query
    conn = self.connect()
  File "/Users/paulrichardmunozbruno/Desktop/proyecto tecnicas de programacion/Gestion_Alimentos.py", line 245, in connect
    raise DatabaseError(f"No se pudo conectar después de {self.max_attempts} intentos: {e}")
DatabaseError: No se pudo conectar después de 3 intentos: 1045 (28000): Access denied for user 'root'@'localhost' (using password: YES)

2025-10-30 10:19:24,143 - root - ERROR - Error de BD en login_user: Error inesperado: No se pudo conectar después de 3 intentos: 1045 (28000): Access denied for user 'root'@'localhost' (using password: YES)
2025-10-30 10:19:40,968 - root - INFO - Aplicación cerrada por el usuario
2025-10-30 10:21:14,288 - root - INFO - Conexión a la base de datos establecida correctamente.
2025-10-30 10:21:24,542 - root - INFO - Login exitoso para: paul (admin)
2025-10-30 10:21:52,063 - root - INFO - Aplicación iniciada correctamente
2025-10-30 10:22:51,265 - root - INFO - Conexión a la base de datos cerrada.
2025-10-30 10:34:32,520 - root - INFO - Conexión a la base de datos establecida correctamente.
2025-10-30 10:34:43,097 - root - INFO - Login exitoso para: paul (admin)
2025-10-30 10:34:45,093 - root - INFO - Aplicación iniciada correctamente
2025-10-30 10:41:21,021 - root - INFO - Conexión a la base de datos cerrada.
2025-10-30 10:41:50,715 - root - INFO - Conexión a la base de datos establecida correctamente.
2025-10-30 10:42:00,664 - root - INFO - Login exitoso para: ana (admin)
2025-10-30 10:42:02,999 - root - INFO - Aplicación iniciada correctamente
2025-10-30 10:42:17,050 - root - INFO - Conexión a la base de datos cerrada.
2025-10-30 10:47:07,397 - root - INFO - Conexión a la base de datos establecida correctamente.
2025-10-30 10:47:10,646 - root - INFO - Aplicación cerrada por el usuario
2025-10-30 10:47:10,647 - root - INFO - Conexión a la base de datos cerrada.
2025-10-30 10:48:57,531 - root - INFO - Conexión a la base de datos establecida correctamente.
2025-10-30 10:49:12,542 - root - INFO - Login exitoso para: ana (admin)
2025-10-30 10:49:16,288 - root - INFO - Aplicación iniciada correctamente
2025-10-30 10:49:28,301 - root - INFO - Conexión a la base de datos cerrada.
2025-10-30 10:56:15,723 - root - INFO - Conexión a la base de datos establecida correctamente.
2025-10-30 10:56:25,844 - root - INFO - Login exitoso para: ana (admin)
2025-10-30 10:56:27,954 - root - INFO - Aplicación iniciada correctamente
2025-10-30 10:57:00,647 - root - INFO - Conexión a la base de datos cerrada.
